<?xml version="1.0" ?>
<!-- =================================================================================== -->
<!-- |    This document was autogenerated by xacro from ack_rover.xacro.urdf           | -->
<!-- |    EDITING THIS FILE BY HAND IS NOT RECOMMENDED                                 | -->
<!-- =================================================================================== -->
<robot name="ack_rover">
  <!-- Specify some standard inertial calculations https://en.wikipedia.org/wiki/List_of_moments_of_inertia -->
  <!-- These make use of xacro's mathematical functionality -->
  <!-- Gazebo tags -->
  <!-- Gazebo Colours -->
  <gazebo reference="chassis">
    <material>Gazebo/Orange</material>
  </gazebo>
  <gazebo reference="rear_left_wheel">
    <material>Gazebo/Blue</material>
  </gazebo>
  <gazebo reference="rear_right_wheel">
    <material>Gazebo/Blue</material>
  </gazebo>
  <gazebo reference="front_right_wheel">
    <material>Gazebo/Black</material>
  </gazebo>
  <gazebo reference="front_left_wheel">
    <material>Gazebo/Black</material>
  </gazebo>
  <gazebo reference="lidar_link">
    <material>Gazebo/Red</material>
  </gazebo>
  <!-- Initial Pose -->
  <gazebo>
    <pose>3.0 0.0 0.0 0 0 0</pose>
  </gazebo>
  <!-- GPS Gazebo Parameters -->
  <gazebo reference="gnss_link">
    <sensor name="GazeboNavSat" type="navsat">
      <always_on>1</always_on>
      <update_rate>25.0</update_rate>
      <visualize>true</visualize>
      <topic>gps/fix</topic>
      <ignition_frame_id>gnss_link</ignition_frame_id>
    </sensor>
  </gazebo>
  <!-- Camera Gazebo Parameters -->
  <gazebo reference="camera_link">
    <material>Gazebo/Black</material>
    <sensor name="camera" type="camera">
      <pose> 0 0 0 0 0 0 </pose>
      <visualize>true</visualize>
      <update_rate>10</update_rate>
      <topic>camera</topic>
      <camera>
        <horizontal_fov>1.089</horizontal_fov>
        <image>
          <format>R8G8B8</format>
          <width>640</width>
          <height>480</height>
        </image>
        <clip>
          <near>0.05</near>
          <far>8.0</far>
        </clip>
      </camera>
      <plugin filename="libgazebo_ros_camera.so" name="ignition::gazebo::systems::Camera">
        <ignition_frame_id>camera_link_optical</ignition_frame_id>
      </plugin>
    </sensor>
    <sensor name="depth_camera" type="rgbd_camera">
      <always_on>true</always_on>
      <visualize>true</visualize>
      <update_rate>5.0</update_rate>
      <topic>depth_camera</topic>
      <ignition_frame_id>camera_link</ignition_frame_id>
      <camera>
        <horizontal_fov>1.047198</horizontal_fov>
        <image>
          <width>640</width>
          <height>480</height>
        </image>
        <clip>
          <near>0.05</near>
          <far>3</far>
        </clip>
      </camera>
      <baseline>0.2</baseline>
      <pointCloudCutoff>0.5</pointCloudCutoff>
      <pointCloudCutoffMax>3.0</pointCloudCutoffMax>
      <distortionK1>0</distortionK1>
      <distortionK2>0</distortionK2>
      <distortionK3>0</distortionK3>
      <distortionT1>0</distortionT1>
      <distortionT2>0</distortionT2>
      <CxPrime>0</CxPrime>
      <Cx>0</Cx>
      <Cy>0</Cy>
      <focalLength>0</focalLength>
      <hackBaseline>0</hackBaseline>
    </sensor>
  </gazebo>
  <!-- Ackermann Controller -->
  <gazebo>
    <plugin filename="ign_ros2_control-system" name="ign_ros2_control::IgnitionROS2ControlPlugin">
      <parameters>/home/brittc/Exodus2025/mobility_ctrl/install/nav2_stanley/share/nav2_stanley/config/ackermann_drive_controller.yaml</parameters>
      <ros>
        <remapping>/ackermann_steering_controller/tf_odometry:=/tf</remapping>
        <remapping>/ackermann_steering_controller/odometry:=/odom</remapping>
        <remapping>/ackermann_steering_controller/reference_unstamped:=/cmd_vel</remapping>
      </ros>
    </plugin>
    <plugin filename="gz-sim-joint-state-publisher-system" name="ignition::gazebo::systems::JointStatePublisher">
      <topic>joint_states</topic>
    </plugin>
  </gazebo>
  <!-- LiDAR -->
  <link name="laser_frame">
    <inertial>
      <origin rpy="0 0 0" xyz="0 0 0"/>
      <mass value="0.125"/>
      <inertia ixx="0.001" ixy="0" ixz="0" iyy="0.001" iyz="0" izz="0.001"/>
    </inertial>
    <collision>
      <origin rpy="0 0 0" xyz="0 0 0"/>
      <geometry>
        <cylinder length="0.055" radius="0.0508"/>
      </geometry>
    </collision>
    <visual>
      <origin rpy="0 0 0" xyz="0 0 0"/>
      <geometry>
        <cylinder length="0.1" radius="0.2"/>
      </geometry>
      <material name="Red"/>
    </visual>
  </link>
  <joint name="laser_joint" type="fixed">
    <parent link="chassis"/>
    <child link="laser_frame"/>
    <origin rpy="0 0 0" xyz="0.5 0 0.8"/>
  </joint>
  <!-- LiDAR -->
  <gazebo reference="laser_frame">
    <material>Gazebo/Red</material>
    <sensor name="lidar" type="gpu_lidar">
      <pose>0 0 0 0 0 0</pose>
      <always_on>true</always_on>
      <visualize>true</visualize>
      <update_rate>10</update_rate>
      <topic>scan</topic>
      <ignition_frame_id>laser_frame</ignition_frame_id>
      <ray>
        <scan>
          <horizontal>
            <samples>360</samples>
            <resolution>1.000000</resolution>
            <min_angle>-3.14</min_angle>
            <max_angle>3.14</max_angle>
          </horizontal>
        </scan>
        <range>
          <min>0.3</min>
          <max>12</max>
          <resolution>0.01</resolution>
        </range>
        <noise>
          <type>gaussian</type>
          <mean>0.0</mean>
          <stddev>0.01</stddev>
        </noise>
      </ray>
    </sensor>
  </gazebo>
  <!-- Colours -->
  <material name="Black">
    <color rgba="0 0 0 1"/>
  </material>
  <material name="Grey">
    <color rgba="0.8 0.8 0.8 1"/>
  </material>
  <material name="Orange">
    <color rgba="1 0.6 0 1"/>
  </material>
  <material name="White">
    <color rgba="1 1 1 1"/>
  </material>
  <material name="Blue">
    <color rgba="0.2 0.2 1 1"/>
  </material>
  <material name="Red">
    <color rgba="1 0.2 0.2 1"/>
  </material>
  <!-- Base Link -->
  <link name="base_link"/>
  <!-- Base_Footprint Link -->
  <joint name="base_footprint_joint" type="fixed">
    <parent link="base_link"/>
    <child link="base_footprint"/>
    <origin rpy="0 0 0" xyz="0 0 0"/>
  </joint>
  <link name="base_footprint">
    </link>
  <!-- Chassis -->
  <!-- Chassis Fixed Joint -->
  <joint name="chassis_joint" type="fixed">
    <origin rpy="0 0 0" xyz="0 0 0.5"/>
    <parent link="base_link"/>
    <child link="chassis"/>
  </joint>
  <!-- Chassis Link -->
  <link name="chassis">
    <visual>
      <origin rpy="0 0 0" xyz="0  0 0.5"/>
      <geometry>
        <box size="2 1 0.5"/>
      </geometry>
      <material name="Orange"/>
    </visual>
    <collision>
      <origin xyz="0 0 0.25"/>
      <geometry>
        <box size="2 1 0.5"/>
      </geometry>
    </collision>
    <inertial>
      <origin rpy="0 0 0" xyz="1.0 0 0.25"/>
      <mass value="0.5"/>
      <inertia ixx="0.05208333333333333" ixy="0.0" ixz="0.0" iyy="0.17708333333333331" iyz="0.0" izz="0.20833333333333331"/>
    </inertial>
  </link>
  <!-- Rear Wheels -->
  <!-- Rear Left Wheel Link -->
  <link name="rear_left_wheel">
    <collision>
      <geometry>
        <cylinder length="0.08" radius="0.3"/>
      </geometry>
    </collision>
    <visual>
      <geometry>
        <cylinder length="0.08" radius="0.3"/>
      </geometry>
      <material name="Blue"/>
    </visual>
    <inertial>
      <origin rpy="0 0 0" xyz="0 0 0"/>
      <mass value="11.3"/>
      <inertia ixx="0.26027666666666666" ixy="0.0" ixz="0.0" iyy="0.26027666666666666" iyz="0.0" izz="0.5085000000000001"/>
    </inertial>
  </link>
  <joint name="rear_left_wheel_joint" type="continuous">
    <origin rpy="-1.57 0 0" xyz="-0.8 0.5 0.3"/>
    <parent link="chassis"/>
    <child link="rear_left_wheel"/>
    <axis xyz="0 0 1"/>
    <dynamics damping="0.2"/>
  </joint>
  <!-- Rear Right Wheel Link -->
  <link name="rear_right_wheel">
    <collision>
      <geometry>
        <cylinder length="0.08" radius="0.3"/>
      </geometry>
    </collision>
    <visual>
      <geometry>
        <cylinder length="0.08" radius="0.3"/>
      </geometry>
      <material name="Blue"/>
    </visual>
    <inertial>
      <origin rpy="0 0 0" xyz="0 0 0"/>
      <mass value="11.3"/>
      <inertia ixx="0.26027666666666666" ixy="0.0" ixz="0.0" iyy="0.26027666666666666" iyz="0.0" izz="0.5085000000000001"/>
    </inertial>
  </link>
  <joint name="rear_right_wheel_joint" type="continuous">
    <origin rpy="-1.57 0 0" xyz="-0.8 -0.5 0.3"/>
    <parent link="chassis"/>
    <child link="rear_right_wheel"/>
    <axis xyz="0 0 1"/>
    <dynamics damping="0.2"/>
  </joint>
  <!-- Front Wheels -->
  <!-- Left Steering Link -->
  <link name="left_wheel_steering">
    <inertial>
      <mass value="0.1"/>
      <inertia ixx="0" ixy="0.0" ixz="0.0" iyy="0.0" iyz="0.0" izz="0.0"/>
    </inertial>
  </link>
  <joint name="left_wheel_steering_joint" type="revolute">
    <origin rpy="1.57 0 0" xyz="0.9 -0.5 0.3"/>
    <parent link="chassis"/>
    <child link="left_wheel_steering"/>
    <axis xyz="0 1 0"/>
    <dynamics damping="0.2"/>
    <limit effort="1000.0" lower="-1.57" upper="1.57" velocity="30"/>
  </joint>
  <!-- Right Steering Link -->
  <link name="right_wheel_steering">
    <inertial>
      <mass value="0.1"/>
      <inertia ixx="0" ixy="0.0" ixz="0.0" iyy="0.0" iyz="0.0" izz="0.0"/>
    </inertial>
  </link>
  <joint name="right_wheel_steering_joint" type="revolute">
    <origin rpy="1.57 0 0" xyz="0.9 0.5 0.3"/>
    <parent link="chassis"/>
    <child link="right_wheel_steering"/>
    <axis xyz="0 1 0"/>
    <dynamics damping="0.2"/>
    <limit effort="1000.0" lower="-1.57" upper="1.57" velocity="30"/>
  </joint>
  <!-- Front Left Wheel Link -->
  <link name="front_left_wheel">
    <collision>
      <geometry>
        <cylinder length="0.08" radius="0.3"/>
      </geometry>
    </collision>
    <visual>
      <geometry>
        <cylinder length="0.08" radius="0.3"/>
      </geometry>
      <material name="Black"/>
    </visual>
    <inertial>
      <origin rpy="0 0 0" xyz="0 0 0"/>
      <mass value="11.3"/>
      <inertia ixx="0.26027666666666666" ixy="0.0" ixz="0.0" iyy="0.26027666666666666" iyz="0.0" izz="0.5085000000000001"/>
    </inertial>
  </link>
  <joint name="front_left_wheel_joint" type="continuous">
    <origin rpy="0 0 0" xyz="0 0 0"/>
    <parent link="left_wheel_steering"/>
    <child link="front_left_wheel"/>
    <axis xyz="0 0 1"/>
    <dynamics damping="0.2"/>
  </joint>
  <!-- Front Right Wheel Link -->
  <link name="front_right_wheel">
    <collision>
      <geometry>
        <cylinder length="0.08" radius="0.3"/>
      </geometry>
    </collision>
    <visual>
      <geometry>
        <cylinder length="0.08" radius="0.3"/>
      </geometry>
      <material name="Black"/>
    </visual>
    <inertial>
      <origin rpy="0 0 0" xyz="0 0 0"/>
      <mass value="11.3"/>
      <inertia ixx="0.26027666666666666" ixy="0.0" ixz="0.0" iyy="0.26027666666666666" iyz="0.0" izz="0.5085000000000001"/>
    </inertial>
  </link>
  <joint name="front_right_wheel_joint" type="continuous">
    <origin rpy="0 0 0" xyz="0 0 0"/>
    <parent link="right_wheel_steering"/>
    <child link="front_right_wheel"/>
    <axis xyz="0 0 1"/>
    <dynamics damping="0.2"/>
  </joint>
  <!-- IMU -->
  <link name="imu_link">
    <visual>
      <geometry>
        <box size="0.1 0.1 0.1"/>
      </geometry>
      <material name="Cyan">
        <color rgba="0 1.0 1.0 1.0"/>
      </material>
    </visual>
    <collision>
      <geometry>
        <box size="0.1 0.1 0.1"/>
      </geometry>
    </collision>
    <inertial>
      <mass value="0.1"/>
      <inertia ixx="0.145833" ixy="0.0" ixz="0.0" iyy="0.145833" iyz="0.0" izz="0.125"/>
    </inertial>
  </link>
  <joint name="imu_joint" type="fixed">
    <parent link="chassis"/>
    <child link="imu_link"/>
    <origin xyz="-0.3 0 0.8"/>
  </joint>
  <gazebo reference="imu_link">
    <sensor name="imu_sensor" type="imu">
      <plugin filename="libignition-gazebo-imu-system.so" name="ignition::gazebo::systems::Imu">
        <initial_orientation_as_reference>false</initial_orientation_as_reference>
      </plugin>
      <always_on>true</always_on>
      <update_rate>100</update_rate>
      <visualize>true</visualize>
      <topic>/imu</topic>
      <enable_metrics>true</enable_metrics>
      <frame_id>imu_link</frame_id>
      <ignition_frame_id>imu_link</ignition_frame_id>
      <imu>
        <orientation_reference_frame>
          <localization>ENU</localization>
        </orientation_reference_frame>
        <angular_velocity>
          <x>
            <noise type="gaussian">
              <mean>0.0</mean>
              <stddev>2e-4</stddev>
              <bias_mean>0.0000075</bias_mean>
              <bias_stddev>0.0000008</bias_stddev>
            </noise>
          </x>
          <y>
            <noise type="gaussian">
              <mean>0.0</mean>
              <stddev>2e-4</stddev>
              <bias_mean>0.0000075</bias_mean>
              <bias_stddev>0.0000008</bias_stddev>
            </noise>
          </y>
          <z>
            <noise type="gaussian">
              <mean>0.0</mean>
              <stddev>2e-4</stddev>
              <bias_mean>0.0000075</bias_mean>
              <bias_stddev>0.0000008</bias_stddev>
            </noise>
          </z>
        </angular_velocity>
        <linear_acceleration>
          <x>
            <noise type="gaussian">
              <mean>0.0</mean>
              <stddev>1.7e-2</stddev>
              <bias_mean>0.1</bias_mean>
              <bias_stddev>0.001</bias_stddev>
            </noise>
          </x>
          <y>
            <noise type="gaussian">
              <mean>0.0</mean>
              <stddev>1.7e-2</stddev>
              <bias_mean>0.1</bias_mean>
              <bias_stddev>0.001</bias_stddev>
            </noise>
          </y>
          <z>
            <noise type="gaussian">
              <mean>0.0</mean>
              <stddev>1.7e-2</stddev>
              <bias_mean>0.1</bias_mean>
              <bias_stddev>0.001</bias_stddev>
            </noise>
          </z>
        </linear_acceleration>
      </imu>
    </sensor>
  </gazebo>
  <!-- GPS -->
  <joint name="gnss_joint" type="fixed">
    <origin rpy="0 0 0" xyz="-0.5 0 0.8"/>
    <parent link="chassis"/>
    <child link="gnss_link"/>
  </joint>
  <link name="gnss_link">
    <collision>
      <geometry>
        <sphere radius="0.1"/>
      </geometry>
    </collision>
    <visual>
      <geometry>
        <sphere radius="0.1"/>
      </geometry>
      <material name="Black"/>
    </visual>
    <inertial>
      <origin rpy="0.3 1.6 -0.4" xyz="-0.5 0 0.8"/>
      <mass value="0.1"/>
      <inertia ixx="0.1" ixy="0.0" ixz="0.0" iyy="0.1" iyz="0.0" izz="0.1"/>
    </inertial>
  </link>
  <!-- Camera -->
  <joint name="camera_joint" type="fixed">
    <parent link="chassis"/>
    <child link="camera_link"/>
    <origin rpy="0 0.18 0" xyz="0 0 0.91"/>
  </joint>
  <link name="camera_link">
    <visual>
      <geometry>
        <box size="0.03 0.07 0.05"/>
      </geometry>
      <material name="Cyan"/>
    </visual>
    <visual>
      <origin xyz="0 0 -0.1"/>
      <geometry>
        <cylinder length="0.2" radius="0.005"/>
      </geometry>
      <material name="Black"/>
    </visual>
  </link>
  <joint name="camera_optical_joint" type="fixed">
    <parent link="camera_link"/>
    <child link="camera_link_optical"/>
    <origin rpy="-1.5707963267948966 0 -1.5707963267948966" xyz="0 0 0"/>
  </joint>
  <link name="camera_link_optical"/>
  <!-- Ackermann Control -->
  <ros2_control name="IgnitionSystem" type="system">
    <hardware>
      <plugin>ign_ros2_control/IgnitionSystem</plugin>
    </hardware>
    <joint name="rear_left_wheel_joint">
      <command_interface name="velocity"/>
      <state_interface name="velocity"/>
      <state_interface name="position"/>
    </joint>
    <joint name="rear_right_wheel_joint">
      <command_interface name="velocity"/>
      <state_interface name="velocity"/>
      <state_interface name="position"/>
    </joint>
    <joint name="left_wheel_steering_joint">
      <!-- <command_interface name="velocity" /> -->
      <command_interface name="position"/>
      <state_interface name="position"/>
    </joint>
    <joint name="right_wheel_steering_joint">
      <!-- <command_interface name="velocity" /> -->
      <command_interface name="position"/>
      <state_interface name="position"/>
    </joint>
  </ros2_control>
</robot>
