<sdf version='1.9'>
  <model name='ack_rover'>
    <link name='base_link'>
      <inertial>
        <pose>0.5242424242424243 0 1.063636363636363 0 0 0</pose>
        <mass>0.82499999999999996</mass>
        <inertia>
          <ixx>0.46807542424242432</ixx>
          <ixy>0</ixy>
          <ixz>0.25277272727272732</ixz>
          <iyy>1.0065905757575759</iyy>
          <iyz>1.688832850946975e-19</iyz>
          <izz>0.84784848484848452</izz>
        </inertia>
      </inertial>
      <collision name='base_link_fixed_joint_lump__chassis_collision'>
        <pose>0 0 0.75 0 0 0</pose>
        <geometry>
          <box>
            <size>2 1 0.5</size>
          </box>
        </geometry>
        <surface>
          <contact>
            <ode/>
          </contact>
          <friction>
            <ode/>
          </friction>
        </surface>
      </collision>
      <collision name='base_link_fixed_joint_lump__gnss_link_collision_1'>
        <pose>-0.5 0 1.3 0 0 0</pose>
        <geometry>
          <sphere>
            <radius>0.10000000000000001</radius>
          </sphere>
        </geometry>
        <surface>
          <contact>
            <ode/>
          </contact>
          <friction>
            <ode/>
          </friction>
        </surface>
      </collision>
      <collision name='base_link_fixed_joint_lump__imu_link_collision_2'>
        <pose>-0.3 0 1.3 0 0 0</pose>
        <geometry>
          <box>
            <size>0.1 0.1 0.1</size>
          </box>
        </geometry>
        <surface>
          <contact>
            <ode/>
          </contact>
          <friction>
            <ode/>
          </friction>
        </surface>
      </collision>
      <collision name='base_link_fixed_joint_lump__laser_frame_collision_3'>
        <pose>0.5 0 1.3 0 0 0</pose>
        <geometry>
          <cylinder>
            <length>0.055</length>
            <radius>0.050799999999999998</radius>
          </cylinder>
        </geometry>
        <surface>
          <contact>
            <ode/>
          </contact>
          <friction>
            <ode/>
          </friction>
        </surface>
      </collision>
      <visual name='base_link_fixed_joint_lump__chassis_visual'>
        <pose>0 0 1 0 0 0</pose>
        <geometry>
          <box>
            <size>2 1 0.5</size>
          </box>
        </geometry>
        <material>
          <script>
            <name>Gazebo/Orange</name>
            <uri>file://media/materials/scripts/gazebo.material</uri>
          </script>
          <diffuse>1 0.75 0 1</diffuse>
          <ambient>1 0.75 0 1</ambient>
        </material>
      </visual>
      <visual name='base_link_fixed_joint_lump__camera_link_visual_1'>
        <pose>0 0 1.41 0 0.18 0</pose>
        <geometry>
          <box>
            <size>0.03 0.07 0.05</size>
          </box>
        </geometry>
        <material>
          <script>
            <name>Gazebo/Black</name>
            <uri>file://media/materials/scripts/gazebo.material</uri>
          </script>
          <diffuse>0 1 1 1</diffuse>
          <ambient>0 1 1 1</ambient>
        </material>
      </visual>
      <visual name='base_link_fixed_joint_lump__camera_link_visual_2'>
        <pose>-0.01790295734258242 0 1.311615630721188 0 0.18 0</pose>
        <geometry>
          <cylinder>
            <length>0.20000000000000001</length>
            <radius>0.0050000000000000001</radius>
          </cylinder>
        </geometry>
        <material>
          <script>
            <name>Gazebo/Black</name>
            <uri>file://media/materials/scripts/gazebo.material</uri>
          </script>
          <diffuse>0 0 0 1</diffuse>
          <ambient>0 0 0 1</ambient>
        </material>
      </visual>
      <visual name='base_link_fixed_joint_lump__gnss_link_visual_3'>
        <pose>-0.5 0 1.3 0 0 0</pose>
        <geometry>
          <sphere>
            <radius>0.10000000000000001</radius>
          </sphere>
        </geometry>
        <material>
          <diffuse>0 0 0 1</diffuse>
          <ambient>0 0 0 1</ambient>
        </material>
      </visual>
      <visual name='base_link_fixed_joint_lump__imu_link_visual_4'>
        <pose>-0.3 0 1.3 0 0 0</pose>
        <geometry>
          <box>
            <size>0.1 0.1 0.1</size>
          </box>
        </geometry>
        <material>
          <diffuse>0 1 1 1</diffuse>
          <ambient>0 1 1 1</ambient>
        </material>
      </visual>
      <visual name='base_link_fixed_joint_lump__laser_frame_visual_5'>
        <pose>0.5 0 1.3 0 0 0</pose>
        <geometry>
          <cylinder>
            <length>0.10000000000000001</length>
            <radius>0.20000000000000001</radius>
          </cylinder>
        </geometry>
        <material>
          <script>
            <name>Gazebo/Red</name>
            <uri>file://media/materials/scripts/gazebo.material</uri>
          </script>
          <diffuse>1 0.25 0.25 1</diffuse>
          <ambient>1 0.25 0.25 1</ambient>
        </material>
      </visual>
      <sensor name='camera' type='camera'>
        <visualize>true</visualize>
        <update_rate>10</update_rate>
        <topic>camera</topic>
        <camera>
          <horizontal_fov>1.089</horizontal_fov>
          <image>
            <format>R8G8B8</format>
            <width>640</width>
            <height>480</height>
          </image>
          <clip>
            <near>0.050000000000000003</near>
            <far>8</far>
          </clip>
        </camera>
        <plugin name='ignition::gazebo::systems::Camera' filename='libgazebo_ros_camera.so'>
          <ignition_frame_id>camera_link_optical</ignition_frame_id>
        </plugin>
        <pose>0 0 1.41 0 0.18 0</pose>
      </sensor>
      <sensor name='depth_camera' type='rgbd_camera'>
        <always_on>true</always_on>
        <visualize>true</visualize>
        <update_rate>5</update_rate>
        <topic>depth_camera</topic>
        <camera>
          <horizontal_fov>1.0471980000000001</horizontal_fov>
          <image>
            <width>640</width>
            <height>480</height>
          </image>
          <clip>
            <near>0.050000000000000003</near>
            <far>3</far>
          </clip>
        </camera>
        <pose>0 0 1.41 0 0.18 0</pose>
        <ignition_frame_id>camera_link</ignition_frame_id>
        <baseline>0.2</baseline>
        <pointCloudCutoff>0.5</pointCloudCutoff>
        <pointCloudCutoffMax>3.0</pointCloudCutoffMax>
        <distortionK1>0</distortionK1>
        <distortionK2>0</distortionK2>
        <distortionK3>0</distortionK3>
        <distortionT1>0</distortionT1>
        <distortionT2>0</distortionT2>
        <CxPrime>0</CxPrime>
        <Cx>0</Cx>
        <Cy>0</Cy>
        <focalLength>0</focalLength>
        <hackBaseline>0</hackBaseline>
      </sensor>
      <sensor name='GazeboNavSat' type='navsat'>
        <always_on>true</always_on>
        <update_rate>25</update_rate>
        <visualize>true</visualize>
        <topic>gps/fix</topic>
        <pose>-0.5 0 1.3 0 -0 0</pose>
        <ignition_frame_id>gnss_link</ignition_frame_id>
      </sensor>
      <sensor name='imu_sensor' type='imu'>
        <plugin name='ignition::gazebo::systems::Imu' filename='libignition-gazebo-imu-system.so'>
          <initial_orientation_as_reference>false</initial_orientation_as_reference>
        </plugin>
        <always_on>true</always_on>
        <update_rate>100</update_rate>
        <visualize>true</visualize>
        <topic>/imu</topic>
        <enable_metrics>true</enable_metrics>
        <imu>
          <orientation_reference_frame>
            <localization>ENU</localization>
          </orientation_reference_frame>
          <angular_velocity>
            <x>
              <noise type='gaussian'>
                <mean>0</mean>
                <stddev>0.00020000000000000001</stddev>
                <bias_mean>7.5000000000000002e-06</bias_mean>
                <bias_stddev>7.9999999999999996e-07</bias_stddev>
              </noise>
            </x>
            <y>
              <noise type='gaussian'>
                <mean>0</mean>
                <stddev>0.00020000000000000001</stddev>
                <bias_mean>7.5000000000000002e-06</bias_mean>
                <bias_stddev>7.9999999999999996e-07</bias_stddev>
              </noise>
            </y>
            <z>
              <noise type='gaussian'>
                <mean>0</mean>
                <stddev>0.00020000000000000001</stddev>
                <bias_mean>7.5000000000000002e-06</bias_mean>
                <bias_stddev>7.9999999999999996e-07</bias_stddev>
              </noise>
            </z>
          </angular_velocity>
          <linear_acceleration>
            <x>
              <noise type='gaussian'>
                <mean>0</mean>
                <stddev>0.017000000000000001</stddev>
                <bias_mean>0.10000000000000001</bias_mean>
                <bias_stddev>0.001</bias_stddev>
              </noise>
            </x>
            <y>
              <noise type='gaussian'>
                <mean>0</mean>
                <stddev>0.017000000000000001</stddev>
                <bias_mean>0.10000000000000001</bias_mean>
                <bias_stddev>0.001</bias_stddev>
              </noise>
            </y>
            <z>
              <noise type='gaussian'>
                <mean>0</mean>
                <stddev>0.017000000000000001</stddev>
                <bias_mean>0.10000000000000001</bias_mean>
                <bias_stddev>0.001</bias_stddev>
              </noise>
            </z>
          </linear_acceleration>
        </imu>
        <pose>-0.3 0 1.3 0 -0 0</pose>
        <frame_id>imu_link</frame_id>
        <ignition_frame_id>imu_link</ignition_frame_id>
      </sensor>
      <sensor name='lidar' type='gpu_lidar'>
        <always_on>true</always_on>
        <visualize>true</visualize>
        <update_rate>10</update_rate>
        <topic>scan</topic>
        <ray>
          <scan>
            <horizontal>
              <samples>360</samples>
              <resolution>1</resolution>
              <min_angle>-3.1400000000000001</min_angle>
              <max_angle>3.1400000000000001</max_angle>
            </horizontal>
          </scan>
          <range>
            <min>0.29999999999999999</min>
            <max>12</max>
            <resolution>0.01</resolution>
          </range>
          <noise>
            <type>gaussian</type>
            <mean>0</mean>
            <stddev>0.01</stddev>
          </noise>
        </ray>
        <pose>0.5 0 1.3 0 -0 0</pose>
        <ignition_frame_id>laser_frame</ignition_frame_id>
      </sensor>
    </link>
    <joint name='left_wheel_steering_joint' type='revolute'>
      <pose relative_to='base_link'>0.9 -0.5 0.8 1.57 0 0</pose>
      <parent>base_link</parent>
      <child>left_wheel_steering</child>
      <axis>
        <xyz>0 1 0</xyz>
        <limit>
          <lower>-1.5700000000000001</lower>
          <upper>1.5700000000000001</upper>
          <effort>1000</effort>
          <velocity>30</velocity>
        </limit>
        <dynamics>
          <damping>0.20000000000000001</damping>
          <friction>0</friction>
          <spring_reference>0</spring_reference>
          <spring_stiffness>0</spring_stiffness>
        </dynamics>
      </axis>
    </joint>
    <link name='left_wheel_steering'>
      <pose relative_to='left_wheel_steering_joint'>0 0 0 0 0 0</pose>
      <inertial>
        <pose>0 0 0 0 0 0</pose>
        <mass>0.10000000000000001</mass>
        <inertia>
          <ixx>0</ixx>
          <ixy>0</ixy>
          <ixz>0</ixz>
          <iyy>0</iyy>
          <iyz>0</iyz>
          <izz>0</izz>
        </inertia>
      </inertial>
    </link>
    <joint name='front_left_wheel_joint' type='revolute'>
      <pose relative_to='left_wheel_steering'>0 0 0 0 0 0</pose>
      <parent>left_wheel_steering</parent>
      <child>front_left_wheel</child>
      <axis>
        <xyz>0 0 1</xyz>
        <limit>
          <lower>-10000000000000000</lower>
          <upper>10000000000000000</upper>
        </limit>
        <dynamics>
          <damping>0.20000000000000001</damping>
          <friction>0</friction>
          <spring_reference>0</spring_reference>
          <spring_stiffness>0</spring_stiffness>
        </dynamics>
      </axis>
    </joint>
    <link name='front_left_wheel'>
      <pose relative_to='front_left_wheel_joint'>0 0 0 0 0 0</pose>
      <inertial>
        <pose>0 0 0 0 0 0</pose>
        <mass>11.300000000000001</mass>
        <inertia>
          <ixx>0.26027666666666671</ixx>
          <ixy>0</ixy>
          <ixz>0</ixz>
          <iyy>0.26027666666666671</iyy>
          <iyz>0</iyz>
          <izz>0.50850000000000006</izz>
        </inertia>
      </inertial>
      <collision name='front_left_wheel_collision'>
        <pose>0 0 0 0 0 0</pose>
        <geometry>
          <cylinder>
            <length>0.080000000000000002</length>
            <radius>0.29999999999999999</radius>
          </cylinder>
        </geometry>
        <surface>
          <contact>
            <ode/>
          </contact>
          <friction>
            <ode/>
          </friction>
        </surface>
      </collision>
      <visual name='front_left_wheel_visual'>
        <pose>0 0 0 0 0 0</pose>
        <geometry>
          <cylinder>
            <length>0.080000000000000002</length>
            <radius>0.29999999999999999</radius>
          </cylinder>
        </geometry>
        <material>
          <script>
            <name>Gazebo/Black</name>
            <uri>file://media/materials/scripts/gazebo.material</uri>
          </script>
          <diffuse>0 0 0 1</diffuse>
          <ambient>0 0 0 1</ambient>
        </material>
      </visual>
    </link>
    <joint name='rear_left_wheel_joint' type='revolute'>
      <pose relative_to='base_link'>-0.8 0.5 0.8 -1.57 0 0</pose>
      <parent>base_link</parent>
      <child>rear_left_wheel</child>
      <axis>
        <xyz>0 0 1</xyz>
        <limit>
          <lower>-10000000000000000</lower>
          <upper>10000000000000000</upper>
        </limit>
        <dynamics>
          <damping>0.20000000000000001</damping>
          <friction>0</friction>
          <spring_reference>0</spring_reference>
          <spring_stiffness>0</spring_stiffness>
        </dynamics>
      </axis>
    </joint>
    <link name='rear_left_wheel'>
      <pose relative_to='rear_left_wheel_joint'>0 0 0 0 0 0</pose>
      <inertial>
        <pose>0 0 0 0 0 0</pose>
        <mass>11.300000000000001</mass>
        <inertia>
          <ixx>0.26027666666666671</ixx>
          <ixy>0</ixy>
          <ixz>0</ixz>
          <iyy>0.26027666666666671</iyy>
          <iyz>0</iyz>
          <izz>0.50850000000000006</izz>
        </inertia>
      </inertial>
      <collision name='rear_left_wheel_collision'>
        <pose>0 0 0 0 0 0</pose>
        <geometry>
          <cylinder>
            <length>0.080000000000000002</length>
            <radius>0.29999999999999999</radius>
          </cylinder>
        </geometry>
        <surface>
          <contact>
            <ode/>
          </contact>
          <friction>
            <ode/>
          </friction>
        </surface>
      </collision>
      <visual name='rear_left_wheel_visual'>
        <pose>0 0 0 0 0 0</pose>
        <geometry>
          <cylinder>
            <length>0.080000000000000002</length>
            <radius>0.29999999999999999</radius>
          </cylinder>
        </geometry>
        <material>
          <script>
            <name>Gazebo/Blue</name>
            <uri>file://media/materials/scripts/gazebo.material</uri>
          </script>
          <diffuse>0.25 0.25 1 1</diffuse>
          <ambient>0.25 0.25 1 1</ambient>
        </material>
      </visual>
    </link>
    <joint name='rear_right_wheel_joint' type='revolute'>
      <pose relative_to='base_link'>-0.8 -0.5 0.8 -1.57 0 0</pose>
      <parent>base_link</parent>
      <child>rear_right_wheel</child>
      <axis>
        <xyz>0 0 1</xyz>
        <limit>
          <lower>-10000000000000000</lower>
          <upper>10000000000000000</upper>
        </limit>
        <dynamics>
          <damping>0.20000000000000001</damping>
          <friction>0</friction>
          <spring_reference>0</spring_reference>
          <spring_stiffness>0</spring_stiffness>
        </dynamics>
      </axis>
    </joint>
    <link name='rear_right_wheel'>
      <pose relative_to='rear_right_wheel_joint'>0 0 0 0 0 0</pose>
      <inertial>
        <pose>0 0 0 0 0 0</pose>
        <mass>11.300000000000001</mass>
        <inertia>
          <ixx>0.26027666666666671</ixx>
          <ixy>0</ixy>
          <ixz>0</ixz>
          <iyy>0.26027666666666671</iyy>
          <iyz>0</iyz>
          <izz>0.50850000000000006</izz>
        </inertia>
      </inertial>
      <collision name='rear_right_wheel_collision'>
        <pose>0 0 0 0 0 0</pose>
        <geometry>
          <cylinder>
            <length>0.080000000000000002</length>
            <radius>0.29999999999999999</radius>
          </cylinder>
        </geometry>
        <surface>
          <contact>
            <ode/>
          </contact>
          <friction>
            <ode/>
          </friction>
        </surface>
      </collision>
      <visual name='rear_right_wheel_visual'>
        <pose>0 0 0 0 0 0</pose>
        <geometry>
          <cylinder>
            <length>0.080000000000000002</length>
            <radius>0.29999999999999999</radius>
          </cylinder>
        </geometry>
        <material>
          <script>
            <name>Gazebo/Blue</name>
            <uri>file://media/materials/scripts/gazebo.material</uri>
          </script>
          <diffuse>0.25 0.25 1 1</diffuse>
          <ambient>0.25 0.25 1 1</ambient>
        </material>
      </visual>
    </link>
    <joint name='right_wheel_steering_joint' type='revolute'>
      <pose relative_to='base_link'>0.9 0.5 0.8 1.57 0 0</pose>
      <parent>base_link</parent>
      <child>right_wheel_steering</child>
      <axis>
        <xyz>0 1 0</xyz>
        <limit>
          <lower>-1.5700000000000001</lower>
          <upper>1.5700000000000001</upper>
          <effort>1000</effort>
          <velocity>30</velocity>
        </limit>
        <dynamics>
          <damping>0.20000000000000001</damping>
          <friction>0</friction>
          <spring_reference>0</spring_reference>
          <spring_stiffness>0</spring_stiffness>
        </dynamics>
      </axis>
    </joint>
    <link name='right_wheel_steering'>
      <pose relative_to='right_wheel_steering_joint'>0 0 0 0 0 0</pose>
      <inertial>
        <pose>0 0 0 0 0 0</pose>
        <mass>0.10000000000000001</mass>
        <inertia>
          <ixx>0</ixx>
          <ixy>0</ixy>
          <ixz>0</ixz>
          <iyy>0</iyy>
          <iyz>0</iyz>
          <izz>0</izz>
        </inertia>
      </inertial>
    </link>
    <joint name='front_right_wheel_joint' type='revolute'>
      <pose relative_to='right_wheel_steering'>0 0 0 0 0 0</pose>
      <parent>right_wheel_steering</parent>
      <child>front_right_wheel</child>
      <axis>
        <xyz>0 0 1</xyz>
        <limit>
          <lower>-10000000000000000</lower>
          <upper>10000000000000000</upper>
        </limit>
        <dynamics>
          <damping>0.20000000000000001</damping>
          <friction>0</friction>
          <spring_reference>0</spring_reference>
          <spring_stiffness>0</spring_stiffness>
        </dynamics>
      </axis>
    </joint>
    <link name='front_right_wheel'>
      <pose relative_to='front_right_wheel_joint'>0 0 0 0 0 0</pose>
      <inertial>
        <pose>0 0 0 0 0 0</pose>
        <mass>11.300000000000001</mass>
        <inertia>
          <ixx>0.26027666666666671</ixx>
          <ixy>0</ixy>
          <ixz>0</ixz>
          <iyy>0.26027666666666671</iyy>
          <iyz>0</iyz>
          <izz>0.50850000000000006</izz>
        </inertia>
      </inertial>
      <collision name='front_right_wheel_collision'>
        <pose>0 0 0 0 0 0</pose>
        <geometry>
          <cylinder>
            <length>0.080000000000000002</length>
            <radius>0.29999999999999999</radius>
          </cylinder>
        </geometry>
        <surface>
          <contact>
            <ode/>
          </contact>
          <friction>
            <ode/>
          </friction>
        </surface>
      </collision>
      <visual name='front_right_wheel_visual'>
        <pose>0 0 0 0 0 0</pose>
        <geometry>
          <cylinder>
            <length>0.080000000000000002</length>
            <radius>0.29999999999999999</radius>
          </cylinder>
        </geometry>
        <material>
          <script>
            <name>Gazebo/Black</name>
            <uri>file://media/materials/scripts/gazebo.material</uri>
          </script>
          <diffuse>0 0 0 1</diffuse>
          <ambient>0 0 0 1</ambient>
        </material>
      </visual>
    </link>
    <pose>3.0 0.0 0.0 0 0 0</pose>
    <plugin name='ign_ros2_control::IgnitionROS2ControlPlugin' filename='ign_ros2_control-system'>
      <parameters>/home/brittc/Exodus2025/mobility_ctrl/install/nav2_stanley/share/nav2_stanley/config/ackermann_drive_controller.yaml</parameters>
      <ros>
        <remapping>/ackermann_steering_controller/tf_odometry:=/tf</remapping>
        <remapping>/ackermann_steering_controller/odometry:=/odom</remapping>
        <remapping>/ackermann_steering_controller/reference_unstamped:=/cmd_vel</remapping>
      </ros>
    </plugin>
    <plugin name='ignition::gazebo::systems::JointStatePublisher' filename='gz-sim-joint-state-publisher-system'>
      <topic>joint_states</topic>
    </plugin>
    <frame name='base_footprint_joint' attached_to='base_link'>
      <pose>0 0 0 0 -0 0</pose>
    </frame>
    <frame name='base_footprint' attached_to='base_footprint_joint'/>
    <frame name='camera_optical_joint' attached_to='camera_link'>
      <pose>0 0 0 -1.5708 -0 -1.5708</pose>
    </frame>
    <frame name='camera_link_optical' attached_to='camera_optical_joint'/>
    <frame name='camera_joint' attached_to='chassis'>
      <pose>0 0 0.91 0 0.18 0</pose>
    </frame>
    <frame name='camera_link' attached_to='camera_joint'/>
    <frame name='gnss_joint' attached_to='chassis'>
      <pose>-0.5 0 0.8 0 -0 0</pose>
    </frame>
    <frame name='gnss_link' attached_to='gnss_joint'/>
    <frame name='imu_joint' attached_to='chassis'>
      <pose>-0.3 0 0.8 0 -0 0</pose>
    </frame>
    <frame name='imu_link' attached_to='imu_joint'/>
    <frame name='laser_joint' attached_to='chassis'>
      <pose>0.5 0 0.8 0 -0 0</pose>
    </frame>
    <frame name='laser_frame' attached_to='laser_joint'/>
    <frame name='chassis_joint' attached_to='base_link'>
      <pose>0 0 0.5 0 -0 0</pose>
    </frame>
    <frame name='chassis' attached_to='chassis_joint'/>
  </model>
</sdf>
